<?xml version="1.0"?>
<robot name="wrist" xmlns:xacro="http://ros.org/wiki/xacro">

    <xacro:include filename="$(find hsrb_description)/urdf/wrist_v0/wrist.gazebo.xacro"/>
    <xacro:include filename="$(find hsrb_parts_description)/urdf/sensors/minebea_ft_sensor.urdf.xacro"/>

    <!-- wrist -->
    <xacro:macro name="hsrb_wrist" params="prefix robot_namespace parent *origin">
        <joint name="${prefix}_flex_joint" type="revolute">
            <origin xyz="0.0 0.0 0.0" rpy="0.0 0.0 0.0" />
            <axis xyz="0.0 -1.0 0.0" />
            <limit effort="100.0" velocity="1.5" lower="-1.92" upper="1.22" />
            <parent link="${parent}" />
            <child link="${prefix}_flex_link" />
            <dynamics damping="1.0"/>
        </joint>

        <link name="${prefix}_flex_link">
            <inertial>
                <mass value="0.681225"/>
                <origin xyz="0.000131 -0.003929 0.00217"/>
                <inertia ixx="0.000074353558" ixy="0.000000494515" ixz="0.000000022937"
                    iyy="0.000038432887" iyz="-0.00000255576" izz="0.000064680918"/>
            </inertial>
            <visual>
                <geometry>
                    <mesh filename="package://hsrb_description/meshes/wrist_v0/wrist_flex.dae" />
                </geometry>
                <material name="body_sub" />
            </visual>
            <visual>
                <origin xyz="0.0 0.0 0.04" rpy="0.0 0.0 0.0"/>
                <geometry>
                    <cylinder radius="0.017" length="0.02" />
                </geometry>
                <material name="body_sub" />
            </visual>

            <collision>
                <origin xyz="0.0 0.0 0.025" rpy="0.0 0.0 0.0"/>
                <geometry>
                    <cylinder radius="0.017" length="0.04" />
                </geometry>
            </collision>
        </link>

        <joint name="${prefix}_roll_joint" type="revolute">
            <origin xyz="0.0 0.0 0.0" rpy="0.0 0.0 0.0" />
            <axis xyz="0.0 0.0 1.0" />
            <limit effort="100.0" velocity="1.5" lower="-1.92" upper="3.67" />
            <parent link="${prefix}_flex_link" />
            <child link="${prefix}_ft_sensor_mount_link" />
            <dynamics damping="1.0"/>
        </joint>

        <!-- each link must have mass in URDF so we apply very small mass (10 gram) for this coupling link -->
        <link name="${prefix}_ft_sensor_mount_link">
          <inertial>
            <mass value="0.01"/>
            <inertia ixx="0.001" ixy="0.0" ixz="0.0"
                     iyy="0.001" iyz="0.0"
                     izz="0.001" />
          </inertial>
        </link>

        <joint name="${prefix}_ft_sensor_frame_inverse_joint" type="fixed">
            <origin xyz="0.0 0.0 0.0735" rpy="-${pi} 0.0 0.0"/>
            <parent link="${prefix}_ft_sensor_frame" />
            <child link="${prefix}_roll_link" />
        </joint>

        <link name="${prefix}_roll_link">
            <inertial>
                <mass value="0.761692"/>
                <origin xyz="-0.001416 -0.001547 0.081689"/>
                <inertia ixx="0.000805633819" ixy="-0.000014431758" ixz="0.000028204659"
                    iyy="0.000768077165" iyz="0.000022460226" izz="0.000453406611"/>
            </inertial>
            <visual>
                <geometry>
                    <mesh filename="package://hsrb_description/meshes/wrist_v0/wrist_roll.dae" />
                </geometry>
            </visual>

            <collision>
                <geometry>
                    <mesh filename="package://hsrb_description/meshes/wrist_v0/wrist_roll.stl" />
                </geometry>
            </collision>
        </link>

        <xacro:minebea_ft_sensor
            prefix="${prefix}"
            robot_namespace="${robot_namespace}"
            parent="${prefix}_ft_sensor_mount_link">
            <origin xyz="0.0 0.0 0.0735" rpy="${pi} 0.0 0.0"/>
        </xacro:minebea_ft_sensor>

        <xacro:hsrb_wrist_gazebo prefix="${prefix}"/>
    </xacro:macro>
</robot>
